Workbook

Sheet Panduan
A1: Konten Planner: HrCash dan Cash Impact (8 minggu)
A3: Pengaturan
A4: Tanggal mulai (isi sendiri) | B4: 46314 | C4: Ubah tanggal ini, seluruh jadwal ikut bergeser. Disarankan hari Senin.
A5: Jam unggah Reels / video IG | B5: 12:00 | C5: Kisaran jam ramai 11.00-13.00 dan 19.00-21.00. Ubah di kolom Jam pada sheet Jadwal.
A6: Jam unggah IG feed (gambar) | B6: 19:00
A7: Jam unggah TikTok | B7: 20:30 | C7: Video yang sama dengan Reels, caption sedikit disesuaikan.
A9: Cara pakai
A10: 1. Buka sheet 'Jadwal 8 Minggu'. Tiap baris = satu unggahan (tanggal, jam, platform, kode konten).
A11: 2. Cari file lewat kolom 'Kode konten' di sheet 'Daftar Konten' (ada nama file/folder, hook, dan caption).
A12: 3. Setelah mengunggah, ubah kolom Status menjadi 'Terposting' (ada pilihan dropdown).
A13: 4. Ringkasan di bawah dan kolom 'Terpakai' di Daftar Konten menghitung otomatis.
A14: 5. Kolom berwarna kuning pada sheet Panduan boleh kamu ubah. Sel lain berisi rumus, jangan ditimpa.
A15: 6. Sheet 'Iklan Meta' berisi rencana uji iklan. Mulai setelah minggu ke-1 (akun sudah ada isi).
A17: Peringatan penting
A18: Video lama V1-V7 (folder marketing/video) masih memuat harga Rp289.000. Jangan dipakai. Pakai hanya set K, N, E.
A19: Video set 'harga' (N) menampilkan Rp349.000 dan nomor 081234556757. Pastikan harga masih berlaku saat diunggah.
A20: Konten hukum (lembur, cuti, THR) bersifat informasi umum. THR (video E04) dan cuti (E03) belum diverifikasi sumbernya. Cek dulu sebelum dipakai.
A21: Contoh angka di video dan gambar adalah ilustrasi. Nama karyawan di video adalah contoh.
A23: Ringkasan jadwal (otomatis)
A24: Total unggahan | B24: =COUNTA('Jadwal 8 Minggu'!A5:A400) -> 129
A25: IG Reels | B25: =COUNTIF('Jadwal 8 Minggu'!E5:E400,"IG Reels") -> 40
A26: IG Feed | B26: =COUNTIF('Jadwal 8 Minggu'!E5:E400,"IG Feed") -> 32
A27: TikTok video | B27: =COUNTIF('Jadwal 8 Minggu'!E5:E400,"TikTok") -> 56
A28: TikTok foto | B28: =COUNTIF('Jadwal 8 Minggu'!E5:E400,"TikTok Foto") -> 1
A29: Sudah terposting | B29: =COUNTIF('Jadwal 8 Minggu'!L5:L400,"Terposting") -> 0
A30: Belum terposting | B30: =B24-B29 -> 129
A32: Hashtag dasar
A33: HrCash: #absensikaryawan #hrumkm #payroll #umkmindonesia #pemilikusaha #tipsbisnis #hrd
A34: Umum: #tipskeuangan #produktivitas #dunia kerja #karier #selfimprovement #umkm
A36: Sumber: jadwal dan frekuensi adalah usulan kerja (belum diuji ke akunmu). Jam unggah mengikuti kebiasaan umum dan perlu disesuaikan setelah melihat statistik akun.

Sheet Jadwal 8 Minggu
A1: Jadwal unggah 8 minggu
A2: Tanggal mengikuti 'Tanggal mulai' di sheet Panduan. Hook dan caption terisi otomatis dari sheet Daftar Konten.
A4: No | B4: Tanggal | C4: Hari | D4: Jam | E4: Platform | F4: Format | G4: Kode konten | H4: Hook / judul | I4: Tujuan | J4: Caption (saran) | K4: Catatan | L4: Status
A5: 1 | B5: =Panduan!$B$4+0 -> 46314 | C5: =CHOOSE(WEEKDAY(B5,2),"Senin","Selasa","Rabu","Kamis","Jumat","Sabtu","Minggu") -> Senin | D5: =Panduan!$B$5 -> 12:00 | E5: IG Reels | F5: Video 9:16 | G5: E01 | H5: =IFERROR(INDEX('Daftar Konten'!$D:$D,MATCH(G5,'Daftar Konten'!$A:$A,0)),"") -> Cara hitung lembur: mulai dari upah sejam | I5: Edukasi | J5: =IFERROR(INDEX('Daftar Konten'!$G:$G,MATCH(G5,'Daftar Konten'!$A:$A,0)),"") -> Hitung lembur mulai dari upah sejam: upah sebulan dibagi 173. Simpan untuk dihitung ulang. Informasi umum, cek aturan terbaru. | K5: Unggah ke Reels | L5: Belum
A6: 2 | B6: =Panduan!$B$4+0 -> 46314 | C6: =CHOOSE(WEEKDAY(B6,2),"Senin","Selasa","Rabu","Kamis","Jumat","Sabtu","Minggu") -> Senin | D6: =Panduan!$B$6 -> 19:00 | E6: IG Feed | F6: Carousel 3 gambar | G6: IG1 | H6: =IFERROR(INDEX('Daftar Konten'!$D:$D,MATCH(G6,'Daftar Konten'!$A:$A,0)),"") -> Katanya masuk jam 8. Buktinya mana? | I6: Masalah owner | J6: =IFERROR(INDEX('Daftar Konten'!$G:$G,MATCH(G6,'Daftar Konten'!$A:$A,0)),"") -> Katanya sudah masuk jam 8, tapi buktinya tidak ada. Absen yang benar punya bukti: selfie, lokasi, jam otomatis. Pernah mengalami ini? Tulis di komentar. Mau tanya-tanya, WA 081234556757. | K6: Unggah di feed | L6: Belum
A7: 3 | B7: =Panduan!$B$4+0 -> 46314 | C7: =CHOOSE(WEEKDAY(B7,2),"Senin","Selasa","Rabu","Kamis","Jumat","Sabtu","Minggu") -> Senin | D7: =Panduan!$B$7 -> 20:30 | E7: TikTok | F7: Video 9:16 | G7: E01 | H7: =IFERROR(INDEX('Daftar Konten'!$D:$D,MATCH(G7,'Daftar Konten'!$A:$A,0)),"") -> Cara hitung lembur: mulai dari upah sejam | I7: Edukasi | J7: =IFERROR(INDEX('Daftar Konten'!$G:$G,MATCH(G7,'Daftar Konten'!$A:$A,0)),"") -> Hitung lembur mulai dari upah sejam: upah sebulan dibagi 173. Simpan untuk dihitung ulang. Informasi umum, cek aturan terbaru. | K7: Video sama, caption disesuaikan | L7: Belum
A8: 4 | B8: =Panduan!$B$4+1 -> 46315 | C8: =CHOOSE(WEEKDAY(B8,2),"Senin","Selasa","Rabu","Kamis","Jumat","Sabtu","Minggu") -> Selasa | D8: =Panduan!$B$5 -> 12:00 | E8: IG Reels | F8: Video 9:16 | G8: F01 | H8: =IFERROR(INDEX('Daftar Konten'!$D:$D,MATCH(G8,'Daftar Konten'!$A:$A,0)),"") -> Jadwal shift yang adil: 3 aturan dasar | I8: Edukasi | J8: =IFERROR(INDEX('Daftar Konten'!$G:$G,MATCH(G8,'Daftar Konten'!$A:$A,0)),"") -> Jadwal shift yang adil: 3 aturan dasar Setuju? Tulis di komentar. | K8: Unggah ke Reels | L8: Belum
A9: 5 | B9: =Panduan!$B$4+1 -> 46315 | C9: =CHOOSE(WEEKDAY(B9,2),"Senin","Selasa","Rabu","Kamis","Jumat","Sabtu","Minggu") -> Selasa | D9: =Panduan!$B$7 -> 20:30 | E9: TikTok | F9: Video 9:16 | G9: F01 | H9: =IFERROR(INDEX('Daftar Konten'!$D:$D,MATCH(G9,'Daftar Konten'!$A:$A,0)),"") -> Jadwal shift yang adil: 3 aturan dasar | I9: Edukasi | J9: =IFERROR(INDEX('Daftar Konten'!$G:$G,MATCH(G9,'Daftar Konten'!$A:$A,0)),"") -> Jadwal shift yang adil: 3 aturan dasar Setuju? Tulis di komentar. | K9: Video sama, caption disesuaikan | L9: Belum
A10: 6 | B10: =Panduan!$B$4+2 -> 46316 | C10: =CHOOSE(WEEKDAY(B10,2),"Senin","Selasa","Rabu","Kamis","Jumat","Sabtu","Minggu") -> Rabu | D10: =Panduan!$B$5 -> 12:00 | E10: IG Reels | F10: Video 9:16 | G10: E16 | H10: =IFERROR(INDEX('Daftar Konten'!$D:$D,MATCH(G10,'Daftar Konten'!$A:$A,0)),"") -> HrCash dalam 20 detik. | I10: Promosi | J10: =IFERROR(INDEX('Daftar Konten'!$G:$G,MATCH(G10,'Daftar Konten'!$A:$A,0)),"") -> Tur singkat HrCash: PIN, lokasi, selfie, selesai. Mau tahu lebih banyak? Tulis di komentar. | K10: Unggah ke Reels | L10: Belum
A11: 7 | B11: =Panduan!$B$4+2 -> 46316 | C11: =CHOOSE(WEEKDAY(B11,2),"Senin","Selasa","Rabu","Kamis","Jumat","Sabtu","Minggu") -> Rabu | D11: =Panduan!$B$6 -> 19:00 | E11: IG Feed | F11: Gambar 4:5 | G11: P01 | H11: =IFERROR(INDEX('Daftar Konten'!$D:$D,MATCH(G11,'Daftar Konten'!$A:$A,0)),"") -> Gaji habis sebelum tanggal tua? Cek 3 bocor halus ini | I11: Edukasi/Interaksi | J11: =IFERROR(INDEX('Daftar Konten'!$G:$G,MATCH(G11,'Daftar Konten'!$A:$A,0)),"") -> Gaji cepat habis padahal merasa tidak belanja besar? Sering kali bocornya halus. Catat pengeluaran 1 bulan penuh, lalu lihat totalnya. Simpan postingan ini untuk dicek di akhir bulan. | K11: Unggah di feed | L11: Belum
A12: 8 | B12: =Panduan!$B$4+2 -> 46316 | C12: =CHOOSE(WEEKDAY(B12,2),"Senin","Selasa","Rabu","Kamis","Jumat","Sabtu","Minggu") -> Rabu | D12: =Panduan!$B$7 -> 20:30 | E12: TikTok | F12: Video 9:16 | G12: E16 | H12: =IFERROR(INDEX('Daftar Konten'!$D:$D,MATCH(G12,'Daftar Konten'!$A:$A,0)),"") -> HrCash dalam 20 detik. | I12: Promosi | J12: =IFERROR(INDEX('Daftar Konten'!$G:$G,MATCH(G12,'Daftar Konten'!$A:$A,0)),"") -> Tur singkat HrCash: PIN, lokasi, selfie, selesai. Mau tahu lebih banyak? Tulis di komentar. | K12: Video sama, caption disesuaikan | L12: Belum
A13: 9 | B13: =Panduan!$B$4+2 -> 46316 | C13: =CHOOSE(WEEKDAY(B13,2),"Senin","Selasa","Rabu","Kamis","Jumat","Sabtu","Minggu") -> Rabu | D13: =Panduan!$B$7 -> 20:30 | E13: TikTok Foto | F13: Foto 3 slide 9:16 | G13: TT1 | H13: =IFERROR(INDEX('Daftar Konten'!$D:$D,MATCH(G13,'Daftar Konten'!$A:$A,0)),"") -> Katanya masuk jam 8. Buktinya mana? | I13: Masalah owner | J13: =IFERROR(INDEX('Daftar Konten'!$G:$G,MATCH(G13,'Daftar Konten'!$A:$A,0)),"") -> Katanya masuk jam 8, buktinya mana? Absen pakai bukti: selfie + lokasi + jam otomatis. Pernah kejadian? Komen ya. | K13: Mode foto TikTok | L13: Belum
A14: 10 | B14: =Panduan!$B$4+3 -> 46317 | C14: =CHOOSE(WEEKDAY(B14,2),"Senin","Selasa","Rabu","Kamis","Jumat","Sabtu","Minggu") -> Kamis | D14: =Panduan!$B$5 -> 12:00 | E14: IG Reels | F14: Video 9:16 | G14: F21 | H14: =IFERROR(INDEX('Daftar Konten'!$D:$D,MATCH(G14,'Daftar Konten'!$A:$A,0)),"") -> POV: Karyawan chat 'macet, Pak' jam 8 lewat 5 | I14: Promosi | J14: =IFERROR(INDEX('Daftar Konten'!$G:$G,MATCH(G14,'Daftar Konten'!$A:$A,0)),"") -> POV: Karyawan chat 'macet, Pak' jam 8 lewat 5 Setuju? Tulis di komentar. | K14: Unggah ke Reels | L14: Belum
A15: 11 | B15: =Panduan!$B$4+3 -> 46317 | C15: =CHOOSE(WEEKDAY(B15,2),"Senin","Selasa","Rabu","Kamis","Jumat","Sabtu","Minggu") -> Kamis | D15: =Panduan!$B$7 -> 20:30 | E15: TikTok | F15: Video 9:16 | G15: F21 | H15: =IFERROR(INDEX('Daftar Konten'!$D:$D,MATCH(G15,'Daftar Konten'!$A:$A,0)),"") -> POV: Karyawan chat 'macet, Pak' jam 8 lewat 5 | I15: Promosi | J15: =IFERROR(INDEX('Daftar Konten'!$G:$G,MATCH(G15,'Daftar Konten'!$A:$A,0)),"") -> POV: Karyawan chat 'macet, Pak' jam 8 lewat 5 Setuju? Tulis di komentar. | K15: Video sama, caption disesuaikan | L15: Belum
A16: 12 | B16: =Panduan!$B$4+4 -> 46318 | C16: =CHOOSE(WEEKDAY(B16,2),"Senin","Selasa","Rabu","Kamis","Jumat","Sabtu","Minggu") -> Jumat | D16: =Panduan!$B$5 -> 12:00 | E16: IG Reels | F16: Video 9:16 | G16: F36 | H16: =IFERROR(INDEX('Daftar Konten'!$D:$D,MATCH(G16,'Daftar Konten'!$A:$A,0)),"") -> Punya warung makan? Begini absen karyawannya | I16: Interaksi | J16: =IFERROR(INDEX('Daftar Konten'!$G:$G,MATCH(G16,'Daftar Konten'!$A:$A,0)),"") -> Punya warung makan? Begini absen karyawannya Setuju? Tulis di komentar. | K16: Unggah ke Reels | L16: Belum
A17: 13 | B17: =Panduan!$B$4+4 -> 46318 | C17: =CHOOSE(WEEKDAY(B17,2),"Senin","Selasa","Rabu","Kamis","Jumat","Sabtu","Minggu") -> Jumat | D17: =Panduan!$B$6 -> 19:00 | E17: IG Feed | F17: Gambar 4:5 | G17: P61 | H17: =IFERROR(INDEX('Daftar Konten'!$D:$D,MATCH(G17,'Daftar Konten'!$A:$A,0)),"") -> 3 kebiasaan keuangan sehat | I17: Edukasi/Interaksi | J17: =IFERROR(INDEX('Daftar Konten'!$G:$G,MATCH(G17,'Daftar Konten'!$A:$A,0)),"") -> Tiga kebiasaan kecil yang bikin keuangan lebih sehat. Mulai satu dulu. Informasi umum. | K17: Unggah di feed | L17: Belum
A18: 14 | B18: =Panduan!$B$4+4 -> 46318 | C18: =CHOOSE(WEEKDAY(B18,2),"Senin","Selasa","Rabu","Kamis","Jumat","Sabtu","Minggu") -> Jumat | D18: =Panduan!$B$7 -> 20:30 | E18: TikTok | F18: Video 9:16 | G18: F36 | H18: =IFERROR(INDEX('Daftar Konten'!$D:$D,MATCH(G18,'Daftar Konten'!$A:$A,0)),"") -> Punya warung makan? Begini absen karyawannya | I18: Interaksi | J18: =IFERROR(INDEX('Daftar Konten'!$G:$G,MATCH(G18,'Daftar Konten'!$A:$A,0)),"") -> Punya warung makan? Begini absen karyawannya Setuju? Tulis di komentar. | K18: Video sama, caption disesuaikan | L18: Belum
A19: 15 | B19: =Panduan!$B$4+5 -> 46319 | C19: =CHOOSE(WEEKDAY(B19,2),"Senin","Selasa","Rabu","Kamis","Jumat","Sabtu","Minggu") -> Sabtu | D19: =Panduan!$B$7 -> 20:30 | E19: TikTok | F19: Video 9:16 | G19: N01 | H19: =IFERROR(INDEX('Daftar Konten'!$D:$D,MATCH(G19,'Daftar Konten'!$A:$A,0)),"") -> POV: Pukul 7 pagi, HP owner sudah bunyi. | I19: Promosi ringan | J19: =IFERROR(INDEX('Daftar Konten'!$G:$G,MATCH(G19,'Daftar Konten'!$A:$A,0)),"") -> POV: Pukul 7 pagi, HP owner sudah bunyi. Setuju? Tulis di komentar. | K19: Khusus TikTok akhir pekan | L19: Belum
A20: 16 | B20: =Panduan!$B$4+6 -> 46320 | C20: =CHOOSE(WEEKDAY(B20,2),"Senin","Selasa","Rabu","Kamis","Jumat","Sabtu","Minggu") -> Minggu | D20: =Panduan!$B$6 -> 19:00 | E20: IG Feed | F20: Gambar 4:5 | G20: P11 | H20: =IFERROR(INDEX('Daftar Konten'!$D:$D,MATCH(G20,'Daftar Konten'!$A:$A,0)),"") -> Side hustle modal di bawah Rp1 juta | I20: Edukasi/Interaksi | J20: =IFERROR(INDEX('Daftar Konten'!$G:$G,MATCH(G20,'Daftar Konten'!$A:$A,0)),"") -> Ide side hustle dengan modal kecil. Pilih satu, coba 30 hari, lalu evaluasi. Ide mana yang paling cocok denganmu? | K20: Unggah di feed | L20: Belum
A21: 17 | B21: =Panduan!$B$4+6 -> 46320 | C21: =CHOOSE(WEEKDAY(B21,2),"Senin","Selasa","Rabu","Kamis","Jumat","Sabtu","Minggu") -> Minggu | D21: =Panduan!$B$7 -> 20:30 | E21: TikTok | F21: Video 9:16 | G21: N05 | H21: =IFERROR(INDEX('Daftar Konten'!$D:$D,MATCH(G21,'Daftar Konten'!$A:$A,0)),"") -> Berapa jam setahun kamu habiskan urus gaji? | I21: Promosi ringan | J21: =IFERROR(INDEX('Daftar Konten'!$G:$G,MATCH(G21,'Daftar Konten'!$A:$A,0)),"") -> Berapa jam setahun kamu habiskan urus gaji? Setuju? Tulis di komentar. | K21: Khusus TikTok akhir pekan | L21: Belum
A22: 18 | B22: =Panduan!$B$4+7 -> 46321 | C22: =CHOOSE(WEEKDAY(B22,2),"Senin","Selasa","Rabu","Kamis","Jumat","Sabtu","Minggu") -> Senin | D22: =Panduan!$B$5 -> 12:00 | E22: IG Reels | F22: Video 9:16 | G22: F51 | H22: =IFERROR(INDEX('Daftar Konten'!$D:$D,MATCH(G22,'Daftar Konten'!$A:$A,0)),"") -> Apa itu UMK? Penjelasan singkat | I22: Interaksi | J22: =IFERROR(INDEX('Daftar Konten'!$G:$G,MATCH(G22,'Daftar Konten'!$A:$A,0)),"") -> Apa itu UMK? Penjelasan singkat Setuju? Tulis di komentar. | K22: Unggah ke Reels | L22: Belum
A23: 19 | B23: =Panduan!$B$4+7 -> 46321 | C23: =CHOOSE(WEEKDAY(B23,2),"Senin","Selasa","Rabu","Kamis","Jumat","Sabtu","Minggu") -> Senin | D23: =Panduan!$B$6 -> 19:00 | E23: IG Feed | F23: Gambar 4:5 | G23: P81 | H23: =IFERROR(INDEX('Daftar Konten'!$D:$D,MATCH(G23,'Daftar Konten'!$A:$A,0)),"") -> Cara membuat anggaran bulanan | I23: Edukasi/Interaksi | J23: =IFERROR(INDEX('Daftar Konten'!$G:$G,MATCH(G23,'Daftar Konten'!$A:$A,0)),"") -> Cara membuat anggaran bulanan dalam 4 langkah. Simpan. | K23: Unggah di feed | L23: Belum
A24: 20 | B24: =Panduan!$B$4+7 -> 46321 | C24: =CHOOSE(WEEKDAY(B24,2),"Senin","Selasa","Rabu","Kamis","Jumat","Sabtu","Minggu") -> Senin | D24: =Panduan!$B$7 -> 20:30 | E24: TikTok | F24: Video 9:16 | G24: F51 | H24: =IFERROR(INDEX('Daftar Konten'!$D:$D,MATCH(G24,'Daftar Konten'!$A:$A,0)),"") -> Apa itu UMK? Penjelasan singkat | I24: Interaksi | J24: =IFERROR(INDEX('Daftar Konten'!$G:$G,MATCH(G24,'Daftar Konten'!$A:$A,0)),"") -> Apa itu UMK? Penjelasan singkat Setuju? Tulis di komentar. | K24: Video sama, caption disesuaikan | L24: Belum
A25: 21 | B25: =Panduan!$B$4+8 -> 46322 | C25: =CHOOSE(WEEKDAY(B25,2),"Senin","Selasa","Rabu","Kamis","Jumat","Sabtu","Minggu") -> Selasa | D25: =Panduan!$B$5 -> 12:00 | E25: IG Reels | F25: Video 9:16 | G25: E28 | H25: =IFERROR(INDEX('Daftar Konten'!$D:$D,MATCH(G25,'Daftar Konten'!$A:$A,0)),"") -> Red flag soal gaji di tempat kerja | I25: Interaksi | J25: =IFERROR(INDEX('Daftar Konten'!$G:$G,MATCH(G25,'Daftar Konten'!$A:$A,0)),"") -> Red flag dan green flag soal gaji di tempat kerja. Pernah menemukan yang mana? | K25: Unggah ke Reels | L25: Belum
A26: 22 | B26: =Panduan!$B$4+8 -> 46322 | C26: =CHOOSE(WEEKDAY(B26,2),"Senin","Selasa","Rabu","Kamis","Jumat","Sabtu","Minggu") -> Selasa | D26: =Panduan!$B$7 -> 20:30 | E26: TikTok | F26: Video 9:16 | G26: E28 | H26: =IFERROR(INDEX('Daftar Konten'!$D:$D,MATCH(G26,'Daftar Konten'!$A:$A,0)),"") -> Red flag soal gaji di tempat kerja | I26: Interaksi | J26: =IFERROR(INDEX('Daftar Konten'!$G:$G,MATCH(G26,'Daftar Konten'!$A:$A,0)),"") -> Red flag dan green flag soal gaji di tempat kerja. Pernah menemukan yang mana? | K26: Video sama, caption disesuaikan | L26: Belum
A27: 23 | B27: =Panduan!$B$4+9 -> 46323 | C27: =CHOOSE(WEEKDAY(B27,2),"Senin","Selasa","Rabu","Kamis","Jumat","Sabtu","Minggu") -> Rabu | D27: =Panduan!$B$5 -> 12:00 | E27: IG Reels | F27: Video 9:16 | G27: E02 | H27: =IFERROR(INDEX('Daftar Konten'!$D:$D,MATCH(G27,'Daftar Konten'!$A:$A,0)),"") -> Lembur itu ada batasnya. | I27: Edukasi | J27: =IFERROR(INDEX('Daftar Konten'!$G:$G,MATCH(G27,'Daftar Konten'!$A:$A,0)),"") -> Lembur ada batas hariannya dan mingguannya. Pastikan jamnya tercatat. Informasi umum, cek aturan terbaru. | K27: Unggah ke Reels | L27: Belum
A28: 24 | B28: =Panduan!$B$4+9 -> 46323 | C28: =CHOOSE(WEEKDAY(B28,2),"Senin","Selasa","Rabu","Kamis","Jumat","Sabtu","Minggu") -> Rabu | D28: =Panduan!$B$6 -> 19:00 | E28: IG Feed | F28: Gambar 4:5 | G28: P21 | H28: =IFERROR(INDEX('Daftar Konten'!$D:$D,MATCH(G28,'Daftar Konten'!$A:$A,0)),"") -> Belajar skill baru dalam 30 hari | I28: Edukasi/Interaksi | J28: =IFERROR(INDEX('Daftar Konten'!$G:$G,MATCH(G28,'Daftar Konten'!$A:$A,0)),"") -> Belajar skill baru dalam 30 hari: fokus satu hal dan konsisten. Skill apa yang mau kamu pelajari? | K28: Unggah di feed | L28: Belum
A29: 25 | B29: =Panduan!$B$4+9 -> 46323 | C29: =CHOOSE(WEEKDAY(B29,2),"Senin","Selasa","Rabu","Kamis","Jumat","Sabtu","Minggu") -> Rabu | D29: =Panduan!$B$7 -> 20:30 | E29: TikTok | F29: Video 9:16 | G29: E02 | H29: =IFERROR(INDEX('Daftar Konten'!$D:$D,MATCH(G29,'Daftar Konten'!$A:$A,0)),"") -> Lembur itu ada batasnya. | I29: Edukasi | J29: =IFERROR(INDEX('Daftar Konten'!$G:$G,MATCH(G29,'Daftar Konten'!$A:$A,0)),"") -> Lembur ada batas hariannya dan mingguannya. Pastikan jamnya tercatat. Informasi umum, cek aturan terbaru. | K29: Video sama, caption disesuaikan | L29: Belum
A30: 26 | B30: =Panduan!$B$4+10 -> 46324 | C30: =CHOOSE(WEEKDAY(B30,2),"Senin","Selasa","Rabu","Kamis","Jumat","Sabtu","Minggu") -> Kamis | D30: =Panduan!$B$5 -> 12:00 | E30: IG Reels | F30: Video 9:16 | G30: F02 | H30: =IFERROR(INDEX('Daftar Konten'!$D:$D,MATCH(G30,'Daftar Konten'!$A:$A,0)),"") -> Memberi feedback: pakai rumus SBI | I30: Edukasi | J30: =IFERROR(INDEX('Daftar Konten'!$G:$G,MATCH(G30,'Daftar Konten'!$A:$A,0)),"") -> Memberi feedback: pakai rumus SBI Setuju? Tulis di komentar. | K30: Unggah ke Reels | L30: Belum
A31: 27 | B31: =Panduan!$B$4+10 -> 46324 | C31: =CHOOSE(WEEKDAY(B31,2),"Senin","Selasa","Rabu","Kamis","Jumat","Sabtu","Minggu") -> Kamis | D31: =Panduan!$B$7 -> 20:30 | E31: TikTok | F31: Video 9:16 | G31: F02 | H31: =IFERROR(INDEX('Daftar Konten'!$D:$D,MATCH(G31,'Daftar Konten'!$A:$A,0)),"") -> Memberi feedback: pakai rumus SBI | I31: Edukasi | J31: =IFERROR(INDEX('Daftar Konten'!$G:$G,MATCH(G31,'Daftar Konten'!$A:$A,0)),"") -> Memberi feedback: pakai rumus SBI Setuju? Tulis di komentar. | K31: Video sama, caption disesuaikan | L31: Belum
A32: 28 | B32: =Panduan!$B$4+11 -> 46325 | C32: =CHOOSE(WEEKDAY(B32,2),"Senin","Selasa","Rabu","Kamis","Jumat","Sabtu","Minggu") -> Jumat | D32: =Panduan!$B$5 -> 12:00 | E32: IG Reels | F32: Video 9:16 | G32: E17 | H32: =IFERROR(INDEX('Daftar Konten'!$D:$D,MATCH(G32,'Daftar Konten'!$A:$A,0)),"") -> Isi Portal Karyawan: 12 menu di satu HP | I32: Promosi | J32: =IFERROR(INDEX('Daftar Konten'!$G:$G,MATCH(G32,'Daftar Konten'!$A:$A,0)),"") -> Isi Portal Karyawan HrCash ada 12 menu. Menu mana yang paling kamu butuhkan? | K32: Unggah ke Reels | L32: Belum
A33: 29 | B33: =Panduan!$B$4+11 -> 46325 | C33: =CHOOSE(WEEKDAY(B33,2),"Senin","Selasa","Rabu","Kamis","Jumat","Sabtu","Minggu") -> Jumat | D33: =Panduan!$B$6 -> 19:00 | E33: IG Feed | F33: Gambar 4:5 | G33: IG2 | H33: =IFERROR(INDEX('Daftar Konten'!$D:$D,MATCH(G33,'Daftar Konten'!$A:$A,0)),"") -> Akhir bulan, rekap absen sampai malam | I33: Masalah owner | J33: =IFERROR(INDEX('Daftar Konten'!$G:$G,MATCH(G33,'Daftar Konten'!$A:$A,0)),"") -> Jam berapa biasanya kamu selesai merekap absen akhir bulan? Jujur saja di komentar. | K33: Unggah di feed | L33: Belum
A34: 30 | B34: =Panduan!$B$4+11 -> 46325 | C34: =CHOOSE(WEEKDAY(B34,2),"Senin","Selasa","Rabu","Kamis","Jumat","Sabtu","Minggu") -> Jumat | D34: =Panduan!$B$7 -> 20:30 | E34: TikTok | F34: Video 9:16 | G34: E17 | H34: =IFERROR(INDEX('Daftar Konten'!$D:$D,MATCH(G34,'Daftar Konten'!$A:$A,0)),"") -> Isi Portal Karyawan: 12 menu di satu HP | I34: Promosi | J34: =IFERROR(INDEX('Daftar Konten'!$G:$G,MATCH(G34,'Daftar Konten'!$A:$A,0)),"") -> Isi Portal Karyawan HrCash ada 12 menu. Menu mana yang paling kamu butuhkan? | K34: Video sama, caption disesuaikan | L34: Belum
A35: 31 | B35: =Panduan!$B$4+12 -> 46326 | C35: =CHOOSE(WEEKDAY(B35,2),"Senin","Selasa","Rabu","Kamis","Jumat","Sabtu","Minggu") -> Sabtu | D35: =Panduan!$B$7 -> 20:30 | E35: TikTok | F35: Video 9:16 | G35: N07 | H35: =IFERROR(INDEX('Daftar Konten'!$D:$D,MATCH(G35,'Daftar Konten'!$A:$A,0)),"") -> 'Saya lupa check out, Pak.' Sering dengar? | I35: Promosi ringan | J35: =IFERROR(INDEX('Daftar Konten'!$G:$G,MATCH(G35,'Daftar Konten'!$A:$A,0)),"") -> 'Saya lupa check out, Pak.' Sering dengar? Setuju? Tulis di komentar. | K35: Khusus TikTok akhir pekan | L35: Belum
A36: 32 | B36: =Panduan!$B$4+13 -> 46327 | C36: =CHOOSE(WEEKDAY(B36,2),"Senin","Selasa","Rabu","Kamis","Jumat","Sabtu","Minggu") -> Minggu | D36: =Panduan!$B$6 -> 19:00 | E36: IG Feed | F36: Gambar 4:5 | G36: P101 | H36: =IFERROR(INDEX('Daftar Konten'!$D:$D,MATCH(G36,'Daftar Konten'!$A:$A,0)),"") | I36: Edukasi/Interaksi | J36: =IFERROR(INDEX('Daftar Konten'!$G:$G,MATCH(G36,'Daftar Konten'!$A:$A,0)),"") | K36: Unggah di feed | L36: Belum
A37: 33 | B37: =Panduan!$B$4+13 -> 46327 | C37: =CHOOSE(WEEKDAY(B37,2),"Senin","Selasa","Rabu","Kamis","Jumat","Sabtu","Minggu") -> Minggu | D37: =Panduan!$B$7 -> 20:30 | E37: TikTok | F37: Video 9:16 | G37: N10 | H37: =IFERROR(INDEX('Daftar Konten'!$D:$D,MATCH(G37,'Daftar Konten'!$A:$A,0)),"") -> Lembur 2 jam, dihitung berapa? | I37: Promosi ringan | J37: =IFERROR(INDEX('Daftar Konten'!$G:$G,MATCH(G37,'Daftar Konten'!$A:$A,0)),"") -> Lembur 2 jam, dihitung berapa? Setuju? Tulis di komentar. | K37: Khusus TikTok akhir pekan | L37: Belum
A38: 34 | B38: =Panduan!$B$4+14 -> 46328 | C38: =CHOOSE(WEEKDAY(B38,2),"Senin","Selasa","Rabu","Kamis","Jumat","Sabtu","Minggu") -> Senin | D38: =Panduan!$B$5 -> 12:00 | E38: IG Reels | F38: Video 9:16 | G38: F22 | H38: =IFERROR(INDEX('Daftar Konten'!$D:$D,MATCH(G38,'Daftar Konten'!$A:$A,0)),"") -> Tipe karyawan saat tanggal gajian | I38: Promosi | J38: =IFERROR(INDEX('Daftar Konten'!$G:$G,MATCH(G38,'Daftar Konten'!$A:$A,0)),"") -> Tipe karyawan saat tanggal gajian Setuju? Tulis di komentar. | K38: Unggah ke Reels | L38: Belum
A39: 35 | B39: =Panduan!$B$4+14 -> 46328 | C39: =CHOOSE(WEEKDAY(B39,2),"Senin","Selasa","Rabu","Kamis","Jumat","Sabtu","Minggu") -> Senin | D39: =Panduan!$B$6 -> 19:00 | E39: IG Feed | F39: Gambar 4:5 | G39: P31 | H39: =IFERROR(INDEX('Daftar Konten'!$D:$D,MATCH(G39,'Daftar Konten'!$A:$A,0)),"") -> Tagihan listrik naik? 4 kebiasaan yang bisa dicoba | I39: Edukasi/Interaksi | J39: =IFERROR(INDEX('Daftar Konten'!$G:$G,MATCH(G39,'Daftar Konten'!$A:$A,0)),"") -> Tagihan listrik naik? Coba kebiasaan kecil ini selama sebulan lalu bandingkan tagihannya. Kebiasaan mana yang sudah kamu lakukan? | K39: Unggah di feed | L39: Belum
A40: 36 | B40: =Panduan!$B$4+14 -> 46328 | C40: =CHOOSE(WEEKDAY(B40,2),"Senin","Selasa","Rabu","Kamis","Jumat","Sabtu","Minggu") -> Senin | D40: =Panduan!$B$7 -> 20:30 | E40: TikTok | F40: Video 9:16 | G40: F22 | H40: =IFERROR(INDEX('Daftar Konten'!$D:$D,MATCH(G40,'Daftar Konten'!$A:$A,0)),"") -> Tipe karyawan saat tanggal gajian | I40: Promosi | J40: =IFERROR(INDEX('Daftar Konten'!$G:$G,MATCH(G40,'Daftar Konten'!$A:$A,0)),"") -> Tipe karyawan saat tanggal gajian Setuju? Tulis di komentar. | K40: Video sama, caption disesuaikan | L40: Belum
A41: 37 | B41: =Panduan!$B$4+15 -> 46329 | C41: =CHOOSE(WEEKDAY(B41,2),"Senin","Selasa","Rabu","Kamis","Jumat","Sabtu","Minggu") -> Selasa | D41: =Panduan!$B$5 -> 12:00 | E41: IG Reels | F41: Video 9:16 | G41: F37 | H41: =IFERROR(INDEX('Daftar Konten'!$D:$D,MATCH(G41,'Daftar Konten'!$A:$A,0)),"") -> Punya kafe? Yang paling sering bikin pusing | I41: Interaksi | J41: =IFERROR(INDEX('Daftar Konten'!$G:$G,MATCH(G41,'Daftar Konten'!$A:$A,0)),"") -> Punya kafe? Yang paling sering bikin pusing Setuju? Tulis di komentar. | K41: Unggah ke Reels | L41: Belum
...

Sheet Daftar Konten
A1: Kode konten | B1: Jenis | C1: File / folder | D1: Hook / judul | E1: Versi | F1: Durasi | G1: Caption (saran) | H1: Catatan | I1: Terpakai di jadwal
A2: K01 | B2: Video 18 detik | C2: marketing/video/animasi/hrcash-K01-chat-tanggal-25-(wa|bersih).mp4 | D2: Tiap tanggal 25, HP bos ramai begini | E2: WA / bersih | F2: ~18 dtk | G2: Tiap tanggal 25, HP bos ramai begini Setuju? Tulis di komentar. | H2: Versi WA: kontak 081234556757. Versi bersih: tanpa ajakan. | I2: =IF(COUNTIF('Jadwal 8 Minggu'!$G$5:$G$400,A2)>0,"Ya","Belum") -> Belum
A3: K02 | B3: Video 18 detik | C3: marketing/video/animasi/hrcash-K02-nol-aplikasi-(wa|bersih).mp4 | D3: Perlu install berapa aplikasi buat absen dan gajian? | E3: WA / bersih | F3: ~18 dtk | G3: Perlu install berapa aplikasi buat absen dan gajian? Setuju? Tulis di komentar. | H3: Versi WA: kontak 081234556757. Versi bersih: tanpa ajakan. | I3: =IF(COUNTIF('Jadwal 8 Minggu'!$G$5:$G$400,A3)>0,"Ya","Belum") -> Belum
A4: K03 | B4: Video 18 detik | C4: marketing/video/animasi/hrcash-K03-kalender-gajian-(wa|bersih).mp4 | D4: Tanggal 25 tidak lagi bikin pusing | E4: WA / bersih | F4: ~18 dtk | G4: Tanggal 25 tidak lagi bikin pusing Setuju? Tulis di komentar. | H4: Versi WA: kontak 081234556757. Versi bersih: tanpa ajakan. | I4: =IF(COUNTIF('Jadwal 8 Minggu'!$G$5:$G$400,A4)>0,"Ya","Belum") -> Belum
A5: K04 | B5: Video 18 detik | C5: marketing/video/animasi/hrcash-K04-titip-absen-(wa|bersih).mp4 | D5: Titip absen itu sudah biasa? | E5: WA / bersih | F5: ~18 dtk | G5: Titip absen itu sudah biasa? Setuju? Tulis di komentar. | H5: Versi WA: kontak 081234556757. Versi bersih: tanpa ajakan. | I5: =IF(COUNTIF('Jadwal 8 Minggu'!$G$5:$G$400,A5)>0,"Ya","Belum") -> Belum
A6: K05 | B6: Video 18 detik | C6: marketing/video/animasi/hrcash-K05-rekap-otomatis-(wa|bersih).mp4 | D6: Rekap absen sebulan? Jangan hitung manual | E6: WA / bersih | F6: ~18 dtk | G6: Rekap absen sebulan? Jangan hitung manual Setuju? Tulis di komentar. | H6: Versi WA: kontak 081234556757. Versi bersih: tanpa ajakan. | I6: =IF(COUNTIF('Jadwal 8 Minggu'!$G$5:$G$400,A6)>0,"Ya","Belum") -> Belum
A7: K06 | B7: Video 18 detik | C7: marketing/video/animasi/hrcash-K06-gaji-dikomplain-(wa|bersih).mp4 | D7: Gaji dikomplain, kok kurang? | E7: WA / bersih | F7: ~18 dtk | G7: Gaji dikomplain, kok kurang? Setuju? Tulis di komentar. | H7: Versi WA: kontak 081234556757. Versi bersih: tanpa ajakan. | I7: =IF(COUNTIF('Jadwal 8 Minggu'!$G$5:$G$400,A7)>0,"Ya","Belum") -> Belum
A8: K07 | B8: Video 18 detik | C8: marketing/video/animasi/hrcash-K07-cuti-lembur-(wa|bersih).mp4 | D8: Cuti dan lembur tanpa kertas | E8: WA / bersih | F8: ~18 dtk | G8: Cuti dan lembur tanpa kertas Setuju? Tulis di komentar. | H8: Versi WA: kontak 081234556757. Versi bersih: tanpa ajakan. | I8: =IF(COUNTIF('Jadwal 8 Minggu'!$G$5:$G$400,A8)>0,"Ya","Belum") -> Belum
A9: K08 | B9: Video 18 detik | C9: marketing/video/animasi/hrcash-K08-kasbon-(wa|bersih).mp4 | D9: Kasbon lupa dicatat? Pusing nagihnya | E9: WA / bersih | F9: ~18 dtk | G9: Kasbon lupa dicatat? Pusing nagihnya Setuju? Tulis di komentar. | H9: Versi WA: kontak 081234556757. Versi bersih: tanpa ajakan. | I9: =IF(COUNTIF('Jadwal 8 Minggu'!$G$5:$G$400,A9)>0,"Ya","Belum") -> Belum
A10: K09 | B10: Video 18 detik | C10: marketing/video/animasi/hrcash-K09-buku-absen-(wa|bersih).mp4 | D10: Buku absen, rekap manual, titip absen. Cukup sudah. | E10: WA / bersih | F10: ~18 dtk | G10: Buku absen, rekap manual, titip absen. Cukup sudah. Setuju? Tulis di komentar. | H10: Versi WA: kontak 081234556757. Versi bersih: tanpa ajakan. | I10: =IF(COUNTIF('Jadwal 8 Minggu'!$G$5:$G$400,A10)>0,"Ya","Belum") -> Belum
A11: K10 | B11: Video 18 detik | C11: marketing/video/animasi/hrcash-K10-hitung-gaji-(wa|bersih).mp4 | D11: Hitung gaji berjam-jam? | E11: WA / bersih | F11: ~18 dtk | G11: Hitung gaji berjam-jam? Setuju? Tulis di komentar. | H11: Versi WA: kontak 081234556757. Versi bersih: tanpa ajakan. | I11: =IF(COUNTIF('Jadwal 8 Minggu'!$G$5:$G$400,A11)>0,"Ya","Belum") -> Belum
A12: N01 | B12: Video 18-19 detik | C12: marketing/video/set-30/bersih/hrcash-N01-pov-jam-7-pagi.mp4 | D12: POV: Pukul 7 pagi, HP owner sudah bunyi. | E12: Bersih | F12: ~18-19 dtk | G12: POV: Pukul 7 pagi, HP owner sudah bunyi. Setuju? Tulis di komentar. | H12: Tanpa harga/kontak | I12: =IF(COUNTIF('Jadwal 8 Minggu'!$G$5:$G$400,A12)>0,"Ya","Belum") -> Ya
A13: N02 | B13: Video 18-19 detik | C13: marketing/video/set-30/harga/hrcash-N02-tiga-tanda-butuh-absen-digital.mp4 | D13: 3 tanda usahamu butuh absen digital. | E13: Harga + WA | F13: ~18-19 dtk | G13: 3 tanda usahamu butuh absen digital. Setuju? Tulis di komentar. | H13: Rp349.000 + 081234556757 di penutup | I13: =IF(COUNTIF('Jadwal 8 Minggu'!$G$5:$G$400,A13)>0,"Ya","Belum") -> Belum
... A161: F60 | B161: Reels/TikTok 20-25 dtk (batch 3) | C161: marketing/video/set-120/hrcash-F60-hak-kewajiban-satu-lembar.mp4 | D161: Hak dan kewajiban: tulis dalam satu lembar | E161: Bersih | F161: ~20-23 dtk | G161: Hak dan kewajiban: tulis dalam satu lembar Setuju? Tulis di komentar. | H161: Tanpa harga/kontak. Konten hukum: informasi umum, cek aturan terbaru. | I161: =IF(COUNTIF('Jadwal 8 Minggu'!$G$5:$G$400,A161)>0,"Ya","Belum") -> Belum
A162: IG1 | B162: Carousel 3 gambar (IG 4:5) | C162: marketing/instagram/ig-carousel-konten-1/slide-1..3.png | D162: Katanya masuk jam 8. Buktinya mana? | G162: Katanya sudah masuk jam 8, tapi buktinya tidak ada. Absen yang benar punya bukti: selfie, lokasi, jam otomatis. Pernah mengalami ini? Tulis di komentar. Mau tanya-tanya, WA 081234556757. | H162: Konten pertama akun baru | I162: =IF(COUNTIF('Jadwal 8 Minggu'!$G$5:$G$400,A162)>0,"Ya","Belum") -> Ya
A163: TT1 | B163: Foto 3 gambar (TikTok 9:16) | C163: marketing/instagram/tiktok-konten-1/slide-1..3.png | D163: Katanya masuk jam 8. Buktinya mana? | G163: Katanya masuk jam 8, buktinya mana? Absen pakai bukti: selfie + lokasi + jam otomatis. Pernah kejadian? Komen ya. | H163: Mode foto TikTok | I163: =IF(COUNTIF('Jadwal 8 Minggu'!$G$5:$G$400,A163)>0,"Ya","Belum") -> Ya
A164: IG2 | B164: Gambar 1 (IG 4:5) | C164: marketing/instagram/ig-post/konten-2-rekap-sampai-malam.png | D164: Akhir bulan, rekap absen sampai malam | G164: Jam berapa biasanya kamu selesai merekap absen akhir bulan? Jujur saja di komentar. | I164: =IF(COUNTIF('Jadwal 8 Minggu'!$G$5:$G$400,A164)>0,"Ya","Belum") -> Ya
A165: IG3 | B165: Gambar 1 (IG 4:5) | C165: marketing/instagram/ig-post/konten-3-gaji-dikomplain.png | D165: Gaji beda hitungan, karyawan protes | G165: Selisih gaji sekecil apa pun bisa jadi debat. Pernah kejadian di tempatmu? | I165: =IF(COUNTIF('Jadwal 8 Minggu'!$G$5:$G$400,A165)>0,"Ya","Belum") -> Ya
A166: IG4 | B166: Gambar 1 (IG 4:5) | C166: marketing/instagram/ig-post/konten-4-titip-absen.png | D166: Satu orang absen, tiga nama tercatat | G166: Titip absen itu rahasia umum. Pernah menemukan di tempat usahamu? | I166: =IF(COUNTIF('Jadwal 8 Minggu'!$G$5:$G$400,A166)>0,"Ya","Belum") -> Ya
A167: IG5 | B167: Gambar 1 (IG 4:5) | C167: marketing/instagram/ig-post/konten-5-siapa-sudah-masuk.png | D167: Jam 9 pagi. Siapa yang sudah masuk? | G167: Sekarang jam berapa? Kamu tahu siapa saja yang sudah masuk hari ini? | I167: =IF(COUNTIF('Jadwal 8 Minggu'!$G$5:$G$400,A167)>0,"Ya","Belum") -> Ya
A168: P01 | B168: Post IG 1 gambar | C168: marketing/instagram/feed-30/P01-bocor-halus-gaji/slide-1..1.png | D168: Gaji habis sebelum tanggal tua? Cek 3 bocor halus ini | G168: Gaji cepat habis padahal merasa tidak belanja besar? Sering kali bocornya halus. Catat pengeluaran 1 bulan penuh, lalu lihat totalnya. Simpan postingan ini untuk dicek di akhir bulan. | H168: Tema umum, tag: Keuangan | I168: =IF(COUNTIF('Jadwal 8 Minggu'!$G$5:$G$400,A168)>0,"Ya","Belum") -> Ya
A169: P02 | B169: Post IG 1 gambar | C169: marketing/instagram/feed-30/P02-quiet-quitting/slide-1..1.png | D169: Quiet quitting bukan soal malas. Ini soal batas. | G169: Bekerja sesuai peran dan jam kerja itu wajar. Yang tidak wajar adalah beban tanpa batas. Setuju atau tidak? Tulis pendapatmu di komentar. | H169: Tema umum, tag: Dunia Kerja | I169: =IF(COUNTIF('Jadwal 8 Minggu'!$G$5:$G$400,A169)>0,"Ya","Belum") -> Belum
A170: P03 | B170: Post IG 1 gambar | C170: marketing/instagram/feed-30/P03-red-flag-green-flag/slide-1..1.png | D170: Red flag vs green flag di tempat kerja | G170: Red flag dan green flag di tempat kerja. Kamu pernah mengalami yang mana? Tag temanmu yang perlu lihat ini. | H170: Tema umum, tag: Dunia Kerja | I170: =IF(COUNTIF('Jadwal 8 Minggu'!$G$5:$G$400,A170)>0,"Ya","Belum") -> Ya
A171: P04 | B171: Post IG 1 gambar | C171: marketing/instagram/feed-30/P04-aturan-50-30-20/slide-1..1.png | D171: Aturan 50/30/20 untuk gaji | G171: Bingung bagi gaji? Mulai dari aturan 50/30/20. Ini panduan awal, boleh disesuaikan dengan kondisimu. Simpan dulu, hitung nanti. | H171: Tema umum, tag: Keuangan | I171: =IF(COUNTIF('Jadwal 8 Minggu'!$G$5:$G$400,A171)>0,"Ya","Belum") -> Ya
A172: P05 | B172: Post IG 1 gambar | C172: marketing/instagram/feed-30/P05-tanda-burnout/slide-1..1.png | D172: Burnout? 5 tanda tubuhmu minta istirahat | G172: Ini tanda umum, bukan diagnosis. Kalau berlangsung lama dan mengganggu, bicarakan dengan profesional. Jaga dirimu. | H172: Tema umum, tag: Kesehatan Mental | I172: =IF(COUNTIF('Jadwal 8 Minggu'!$G$5:$G$400,A172)>0,"Ya","Belum") -> Belum
A173: P06 | B173: Post IG 1 gambar | C173: marketing/instagram/feed-30/P06-tiga-prompt-ai/slide-1..1.png | D173: 3 prompt AI yang beneran kepakai di kerja | G173: Tiga prompt sederhana yang bisa langsung dipakai. Ganti bagian dalam kurung dengan konteksmu. Simpan untuk dicoba. | H173: Tema umum, tag: Ai Dan Produktivitas | I173: =IF(COUNTIF('Jadwal 8 Minggu'!$G$5:$G$400,A173)>0,"Ya","Belum") -> Belum
A174: P07 | B174: Post IG 1 gambar | C174: marketing/instagram/feed-30/P07-no-buy-challenge/slide-1..1.png | D174: No-buy challenge 30 hari: aturan mainnya | G174: No-buy challenge 30 hari: bukan berhenti belanja total, tapi lebih sadar. Berani coba? Tulis tanggal mulaimu di komentar. | H174: Tema umum, tag: Keuangan | I174: =IF(COUNTIF('Jadwal 8 Minggu'!$G$5:$G$400,A174)>0,"Ya","Belum") -> Belum
A175: P08 | B175: Post IG 1 gambar | C175: marketing/instagram/feed-30/P08-poll-wfo-hybrid/slide-1..1.png | D175: WFO, hybrid, atau WFH? Kamu tim mana? | G175: Kamu tim mana? Komen A, B, atau C. Ceritakan alasanmu. | H175: Tema umum, tag: Dunia Kerja | I175: =IF(COUNTIF('Jadwal 8 Minggu'!$G$5:$G$400,A175)>0,"Ya","Belum") -> Belum
A176: P09 | B176: Post IG 1 gambar | C176: marketing/instagram/feed-30/P09-mitos-investasi/slide-1..1.png | D176: Mitos: investasi itu hanya untuk orang kaya | G176: Mitos dan fakta soal investasi. Ini informasi umum, bukan ajakan atau saran investasi. Pelajari dulu dan sesuaikan dengan profil risikomu. | H176: Tema umum, tag: Keuangan | I176: =IF(COUNTIF('Jadwal 8 Minggu'!$G$5:$G$400,A176)>0,"Ya","Belum") -> Belum
A177: P10 | B177: Post IG 1 gambar | C177: marketing/instagram/feed-30/P10-jam-produktif/slide-1..1.png | D177: Jam produktifmu kapan? Cocokkan dengan tugasnya | G177: Cocokkan jenis tugas dengan jam energimu. Kamu paling produktif jam berapa? | H177: Tema umum, tag: Produktivitas | I177: =IF(COUNTIF('Jadwal 8 Minggu'!$G$5:$G$400,A177)>0,"Ya","Belum") -> Belum
A178: P11 | B178: Post IG 2 gambar | C178: marketing/instagram/feed-30/P11-side-hustle-modal-kecil/slide-1..2.png | D178: Side hustle modal di bawah Rp1 juta | G178: Ide side hustle dengan modal kecil. Pilih satu, coba 30 hari, lalu evaluasi. Ide mana yang paling cocok denganmu? | H178: Tema umum, tag: Side Hustle | I178: =IF(COUNTIF('Jadwal 8 Minggu'!$G$5:$G$400,A178)>0,"Ya","Belum") -> Ya
A179: P12 | B179: Post IG 2 gambar | C179: marketing/instagram/feed-30/P12-menolak-lembur/slide-1..2.png | D179: Cara menolak lembur tanpa drama | G179: Menolak lembur tanpa drama itu bisa. Simpan skrip ini untuk dipakai saat dibutuhkan. | H179: Tema umum, tag: Dunia Kerja | I179: =IF(COUNTIF('Jadwal 8 Minggu'!$G$5:$G$400,A179)>0,"Ya","Belum") -> Ya
... A287: P12 | B287: Post IG 3 gambar | C287: marketing/instagram/feed-120/P120-evaluasi-usaha-akhir-bulan/slide-1..3.png | D287: Evaluasi usaha akhir bulan | G287: Evaluasi usaha tiap akhir bulan dengan lima pertanyaan. | H287: Tema umum, tag: Bisnis Kecil | I287: =IF(COUNTIF('Jadwal 8 Minggu'!$G$5:$G$400,A287)>0,"Ya","Belum") -> Ya

Sheet Iklan Meta
A1: Rencana uji iklan Meta Ads (usulan)
A2: Mulai setelah minggu ke-1. Angka budget diisi sendiri (sel kuning). Tidak ada angka hasil yang dijanjikan.
A4: Budget per hari (isi sendiri) | C4: Lama uji per tahap (hari) | D4: 5
A5: Total budget per tahap | B5: =IF(B4="","",B4*D4)
A7: Tahap | B7: Minggu | C7: Tujuan | D7: Kreatif (kode konten) | E7: Alasan | F7: Tujuan kampanye di Meta | G7: Audiens (usulan) | H7: Yang dipantau | I7: Keputusan
A8: 1 | B8: Minggu 1 | C8: Organik dulu | D8: Semua jadwal organik | E8: Mengisi akun dan melihat konten yang disukai audiens | F8: - | G8: - | H8: Jangkauan, simpan, bagikan, komentar | I8: Catat 3 konten terbaik
A9: 2 | B9: Minggu 2 | C9: Uji hook | D9: N33, N49, N51 | E9: Tiga hook berbeda dengan harga Rp349.000 dan kontak WA | F9: Pesan (WhatsApp) | G9: Pemilik usaha kecil, usia 25-55, Indonesia, minat bisnis/UMKM | H9: Tayangan 3 detik, CTR, biaya per pesan | I9: Matikan yang terendah, lanjutkan 2
A10: 3 | B10: Minggu 3 | C10: Uji pesan | D10: N13, N46, N54 | E10: Fokus kecepatan, risiko data, tanpa HRD | F10: Pesan (WhatsApp) | G10: Sama seperti tahap 2 | H10: Tayangan 3 detik, CTR, biaya per pesan | I10: Bandingkan dengan tahap 2
A11: 4 | B11: Minggu 4 | C11: Skala pemenang | D11: 2 kreatif terbaik tahap 2-3 | E11: Naikkan budget bertahap pada yang konsisten | F11: Pesan (WhatsApp) | G11: Perluas minat dan wilayah | H11: Biaya per pesan, jumlah pesan, kualitas prospek | I11: Naikkan 20-30% bila stabil
A12: Cadangan | B12: Kapan saja | C12: Retargeting | D12: E16, E17, E19 (versi bersih) | E12: Menghangatkan yang sudah menonton | F12: Interaksi / Pesan | G12: Penonton video 50%+ | H12: Frekuensi, CTR | I12: Hentikan jika frekuensi tinggi
A15: Catatan: kreatif harga (set N 'harga') memuat Rp349.000 dan 081234556757. Selalu cek kebijakan iklan Meta sebelum menayangkan, terutama untuk klaim hukum (lembur, THR).
